<?xml version="1.0" ?>
<robot name="wheelchair_robot">

  <link name="base_footprint">
    <!-- Add geometry, inertial, and visual elements for the lidar link -->
  </link>

  

  <!-- Manipulator Link -->
  <!-- <link name="manipulator_link"> -->
    <!-- Add geometry, inertial, and visual elements for the manipulator link -->
  <!-- </link> -->

  <!-- Base to Lidar Joint -->


  <!-- Base Link -->
  <link name="base_link">
     <visual>
      <origin
        xyz="0 0 0"
        rpy="0 0 0" />
      <geometry>
        <mesh
          filename="package://wheelchair_description/meshes/body/wheelchair_wo_arm.stl" />
      </geometry>
      <material
        name="">
        <color
          rgba="0.8 0.8 1 1" />
      </material>
    </visual>
    <collision>
      <origin
        xyz="0 0 0"
        rpy="0 0 0" />
      <geometry>
        <mesh
          filename="package://wheelchair_description/meshes/body/wheelchair_wo_arm.stl" />
      </geometry>
    </collision>
  </link>

  <!-- Lidar Link -->
  <link name="rslidar">
    <!-- Add geometry, inertial, and visual elements for the lidar link -->
  </link>

    <!-- Front Right Wheel Link -->
  <link name="front_right_wheel_link">
    <!-- Add geometry, inertial, and visual elements for front right wheel link -->
  </link>

  <!-- Front Left Wheel Link -->
  <link name="front_left_wheel_link">
    <!-- Add geometry, inertial, and visual elements for front left wheel link -->
  </link>

  <!-- Rear Right Wheel Link -->
  <link name="rear_right_wheel_link">
    <!-- Add geometry, inertial, and visual elements for rear right wheel link -->
  </link>

  <!-- Rear Left Wheel Link -->
  <link name="rear_left_wheel_link">
    <!-- Add geometry, inertial, and visual elements for rear left wheel link -->
  </link>

  <link name="camera_link">
    <!-- Add geometry, inertial, and visual elements for the manipulator link -->
  </link>

  <!-- Manipulator Link -->
  <!-- <link name="manipulator_link"> -->
    <!-- Add geometry, inertial, and visual elements for the manipulator link -->
  <!-- </link> -->

  <joint name="foot_to_base_joint" type="fixed">
    <parent link="base_footprint"/>
    <child link="base_link"/>
    <origin xyz="0 0 0.125" rpy="0 0 0"/>
  </joint>

  <!-- Base to Lidar Joint -->
  <joint name="base_to_lidar_joint" type="fixed">
    <parent link="base_link"/>
    <child link="rslidar"/>
    <origin xyz="-0.1869 0 1.4697" rpy="0.0331613 0 -1.57"/>
  </joint>



  <!-- Front Right Wheel Joint -->
  <joint name="front_right_wheel_joint" type="continuous">
    <parent link="base_link"/>
    <child link="front_right_wheel_link"/>
    <origin xyz="0.55 -0.2625 0" rpy="0 0 0"/>
    <axis xyz="0 1 0"/>
  </joint>

  <!-- Front Left Wheel Joint -->
  <joint name="front_left_wheel_joint" type="continuous">
    <parent link="base_link"/>
    <child link="front_left_wheel_link"/>
    <origin xyz="0.55 0.2625 0" rpy="0 0 0"/>
    <axis xyz="0 1 0"/>
  </joint>

  <!-- Rear Right Wheel Joint -->
  <joint name="rear_right_wheel_joint" type="continuous">
    <parent link="base_link"/>
    <child link="rear_right_wheel_link"/>
    <origin xyz="0 -0.280 0" rpy="0 0 0"/>
    <axis xyz="0 1 0"/>
  </joint>

  <!-- Rear Left Wheel Joint -->
  <joint name="rear_left_wheel_joint" type="continuous">
    <parent link="base_link"/>
    <child link="rear_left_wheel_link"/>
    <origin xyz="0 0.280 0" rpy="0 0 0"/>
    <axis xyz="0 1 0"/>
  </joint>



  <!-- 1.394 - 0.125 =  1.269 -->
  <joint name="base_camera_joint" type="fixed">
    <parent link="base_link"/>
    <child link="camera_link"/>
    <!-- <origin xyz="0 0 0.32" rpy="1.5707963 0 1.5707963"/> -->
    <origin xyz="-0.11 0 1.269" rpy="0 0 0"/>
    <axis xyz="0 0 1"/>
  </joint>

  
<!-- <<<<<<<<<<<<<<<<<<<<<<<<<<<<<<      ARM      >>>>>>>>>>>>>>>>>>>>>>>>>>>>>> -->

<link name="manipulator_link">
    <inertial>
      <origin
        xyz="-0.000433277303987328 -3.54664423471128E-05 0.0599427668933796"
        rpy="0 0 0" />
      <mass
        value="0.841070778135659" />
      <inertia
        ixx="0.0017261110801622"
        ixy="2.52746264980217E-06"
        ixz="-3.67690303614961E-05"
        iyy="0.00170987405835604"
        iyz="1.67996364994424E-06"
        izz="0.000904023422915791" />
    </inertial>
    <visual>
      <origin
        xyz="0 0 0"
        rpy="0 0 0" />
      <geometry>
        <mesh
          filename="package://wheelchair_description/meshes/arm/base_link.STL" />
      </geometry>
      <material
        name="">
        <color
          rgba="1 1 1 1" />
      </material>
    </visual>
    <collision>
      <origin
        xyz="0 0 0"
        rpy="0 0 0" />
      <geometry>
        <mesh
          filename="package://wheelchair_description/meshes/arm/base_link.STL" />
      </geometry>
    </collision>
</link>

  <!-- Base to Manipulator Joint -->
<joint name="base_to_manipulator_joint" type="fixed">
    <parent link="base_link"/>
    <child link="manipulator_link"/>
    <origin xyz="0.4416 0.2775 0.5204" rpy="0 0 3.1416"/>
</joint>

<link name="Link1">
    <inertial>
      <origin
        xyz="1.2226305431569E-08 0.0211079974844683 -0.0251854220842269"
        rpy="0 0 0" />
      <mass
        value="0.593563443690403" />
      <inertia
        ixx="0.00126614120341847"
        ixy="-1.294980943835E-08"
        ixz="-9.80120923066996E-09"
        iyy="0.00118168178300364"
        iyz="-0.00021121727444415"
        izz="0.00056135241627747" />
    </inertial>
    <visual>
      <origin
        xyz="0 0 0"
        rpy="0 0 0" />
      <geometry>
        <mesh
          filename="package://wheelchair_description/meshes/arm/link1.STL" />
      </geometry>
      <material
        name="">
        <color
          rgba="1 1 1 1" />
      </material>
    </visual>
    <collision>
      <origin
        xyz="0 0 0"
        rpy="0 0 0" />
      <geometry>
        <mesh
          filename="package://wheelchair_description/meshes/arm/link1.STL" />
      </geometry>
    </collision>
</link>

<joint
    name="joint1"
    type="revolute">
    <origin
      xyz="0 0 0.2405"
      rpy="0 0 0" />
    <parent
      link="manipulator_link" />
    <child
      link="Link1" />
    <axis
      xyz="0 0 1" />
    <limit
      lower="-3.1"
      upper="3.1"
      effort="60"
      velocity="3.14" />
</joint>

<link name="Link2">
    <inertial>
      <origin
        xyz="0.152256463426163 4.75383656106654E-07 -0.00620260383607792"
        rpy="0 0 0" />
      <mass
        value="0.864175046869043" />
      <inertia
        ixx="0.00089150298478414"
        ixy="-2.23268489334765E-08"
        ixz="0.00156246461035015"
        iyy="0.00733754343083901"
        iyz="6.28110889329165E-09"
        izz="0.00697869103915473" />
    </inertial>
    <visual>
      <origin
        xyz="0 0 0"
        rpy="0 0 0" />
      <geometry>
        <mesh
          filename="package://wheelchair_description/meshes/arm/link2.STL" />
      </geometry>
      <material
        name="">
        <color
          rgba="1 1 1 1" />
      </material>
    </visual>
    <collision>
      <origin
        xyz="0 0 0"
        rpy="0 0 0" />
      <geometry>
        <mesh
          filename="package://wheelchair_description/meshes/arm/link2.STL" />
      </geometry>
    </collision>
</link>

<joint
    name="joint2"
    type="revolute">
    <origin
      xyz="0 0 0"
      rpy="1.5708 -1.5708 0" />
    <parent
      link="Link1" />
    <child
      link="Link2" />
    <axis
      xyz="0 0 1" />
    <limit
      lower="-2.268"
      upper="2.268"
      effort="60"
      velocity="3.14" />
</joint>

 <link name="Link3">
    <inertial>
      <origin
        xyz="5.05312670989961E-06 -0.0595925663694732 0.010569069212336"
        rpy="0 0 0" />
      <mass
        value="0.289633681624654" />
      <inertia
        ixx="0.00063737100450158"
        ixy="-7.05261293649751E-08"
        ixz="-3.86643272239426E-08"
        iyy="0.00015648388095025"
        iyz="-0.00014461035994916"
        izz="0.000614178164773085" />
    </inertial>
    <visual>
      <origin
        xyz="0 0 0"
        rpy="0 0 0" />
      <geometry>
        <mesh
          filename="package://wheelchair_description/meshes/arm/link3.STL" />
      </geometry>
      <material
        name="">
        <color
          rgba="1 1 1 1" />
      </material>
    </visual>
    <collision>
      <origin
        xyz="0 0 0"
        rpy="0 0 0" />
      <geometry>
        <mesh
          filename="package://wheelchair_description/meshes/arm/link3.STL" />
      </geometry>
    </collision>
</link>

<joint
    name="joint3"
    type="revolute">
    <origin
      xyz="0.256 0 0"
      rpy="0 0 1.5708" />
    <parent
      link="Link2" />
    <child
      link="Link3" />
    <axis
      xyz="0 0 1" />
    <limit
      lower="-2.355"
      upper="2.355"
      effort="30"
      velocity="3.92" />
</joint>

<link
    name="Link4">
    <inertial>
      <origin
        xyz="1.15516617405898E-06 -0.0180424468598241 -0.0215394748352687"
        rpy="0 0 0" />
      <mass
        value="0.239419768320061" />
      <inertia
        ixx="0.000285938919722783"
        ixy="3.07101359163101E-09"
        ixz="-2.21994118981953E-09"
        iyy="0.000262727540304212"
        iyz="4.4236583260078E-05"
        izz="0.000119888082791859" />
    </inertial>
    <visual>
      <origin
        xyz="0 0 0"
        rpy="0 0 0" />
      <geometry>
        <mesh
          filename="package://wheelchair_description/meshes/arm/link4.STL" />
      </geometry>
      <material
        name="">
        <color
          rgba="1 1 1 1" />
      </material>
    </visual>
    <collision>
      <origin
        xyz="0 0 0"
        rpy="0 0 0" />
      <geometry>
        <mesh
          filename="package://wheelchair_description/meshes/arm/link4.STL" />
      </geometry>
    </collision>
</link>

<joint
    name="joint4"
    type="revolute">
    <origin
      xyz="0 -0.21 0"
      rpy="1.5708 0 0" />
    <parent
      link="Link3" />
    <child
      link="Link4" />
    <axis
      xyz="0 0 1" />
    <limit
      lower="-3.1"
      upper="3.1"
      effort="10"
      velocity="3.92" />
</joint>

<link
    name="Link5">
    <inertial>
      <origin
        xyz="3.19794786262152E-06 -0.0593808368101458 0.00736804250989326"
        rpy="0 0 0" />
      <mass
        value="0.218799761431678" />
      <inertia
        ixx="0.000350540363914072"
        ixy="-3.41781619975602E-08"
        ixz="-1.77056457224373E-08"
        iyy="0.000104927867487581"
        iyz="-7.82431228461971E-05"
        izz="0.000334482418423629" />
    </inertial>
    <visual>
      <origin
        xyz="0 0 0"
        rpy="0 0 0" />
      <geometry>
        <mesh
          filename="package://wheelchair_description/meshes/arm/link5.STL" />
      </geometry>
      <material
        name="">
        <color
          rgba="1 1 1 1" />
      </material>
    </visual>
    <collision>
      <origin
        xyz="0 0 0"
        rpy="0 0 0" />
      <geometry>
        <mesh
          filename="package://wheelchair_description/meshes/arm/link5.STL" />
      </geometry>
    </collision>
</link>

<joint
    name="joint5"
    type="revolute">
    <origin
      xyz="0 0 0"
      rpy="-1.5708 0 0" />
    <parent
      link="Link4" />
    <child
      link="Link5" />
    <axis
      xyz="0 0 1" />
    <limit
      lower="-2.233"
      upper="2.233"
      effort="10"
      velocity="3.92" />
</joint>

<link
    name="Link6">
    <inertial>
      <origin
        xyz="0.000714234511756999 -0.000396718732824521 -0.0126723660946126"
        rpy="0 0 0" />
      <mass
        value="0.0649018034311231" />
      <inertia
        ixx="2.02766547502765E-05"
        ixy="-1.32505200276849E-06"
        ixz="-2.5845091522508E-08"
        iyy="1.87986725225022E-05"
        iyz="3.39471452125439E-09"
        izz="3.17885459163081E-05" />
    </inertial>
    <visual>
      <origin
        xyz="0 0 0"
        rpy="0 0 0" />
      <geometry>
        <mesh
          filename="package://wheelchair_description/meshes/arm/link6.STL" />
      </geometry>
      <material
        name="">
        <color
          rgba="1 1 1 1" />
      </material>
    </visual>
    <collision>
      <origin
        xyz="0 0 0"
        rpy="0 0 0" />
      <geometry>
        <mesh
          filename="package://wheelchair_description/meshes/arm/link6.STL" />
      </geometry>
    </collision>
</link>
<joint
    name="joint6"
    type="revolute">
    <origin
      xyz="0 -0.144 0"
      rpy="1.5708 0 0" />
    <parent
      link="Link5" />
    <child
      link="Link6" />
    <axis
      xyz="0 0 1" />
    <limit
      lower="-6.28"
      upper="6.28"
      effort="10"
      velocity="3.92" />
</joint>


</robot>